[2025-05-28T09:07:06.171+0000] {taskinstance.py:1979} INFO - Dependencies all met for dep_context=non-requeueable deps ti=<TaskInstance: animal_etl_pipeline_v1.extract_animals scheduled__2025-05-27T02:00:00+00:00 [queued]>
[2025-05-28T09:07:06.185+0000] {taskinstance.py:1979} INFO - Dependencies all met for dep_context=requeueable deps ti=<TaskInstance: animal_etl_pipeline_v1.extract_animals scheduled__2025-05-27T02:00:00+00:00 [queued]>
[2025-05-28T09:07:06.185+0000] {taskinstance.py:2193} INFO - Starting attempt 1 of 4
[2025-05-28T09:07:06.204+0000] {taskinstance.py:2217} INFO - Executing <Task(ExtractAnimalsOperator): extract_animals> on 2025-05-27 02:00:00+00:00
[2025-05-28T09:07:06.211+0000] {standard_task_runner.py:60} INFO - Started process 66 to run task
[2025-05-28T09:07:06.214+0000] {standard_task_runner.py:87} INFO - Running: ['airflow', 'tasks', 'run', 'animal_etl_pipeline_v1', 'extract_animals', 'scheduled__2025-05-27T02:00:00+00:00', '--job-id', '5', '--raw', '--subdir', 'DAGS_FOLDER/animal_etl_dag.py', '--cfg-path', '/tmp/tmp0jwdofph']
[2025-05-28T09:07:06.215+0000] {standard_task_runner.py:88} INFO - Job 5: Subtask extract_animals
[2025-05-28T09:07:06.281+0000] {task_command.py:423} INFO - Running <TaskInstance: animal_etl_pipeline_v1.extract_animals scheduled__2025-05-27T02:00:00+00:00 [running]> on host 432e2a45d2a3
[2025-05-28T09:07:06.372+0000] {taskinstance.py:2513} INFO - Exporting env vars: AIRFLOW_CTX_DAG_EMAIL='admin@company.com' AIRFLOW_CTX_DAG_OWNER='data_team' AIRFLOW_CTX_DAG_ID='animal_etl_pipeline_v1' AIRFLOW_CTX_TASK_ID='extract_animals' AIRFLOW_CTX_EXECUTION_DATE='2025-05-27T02:00:00+00:00' AIRFLOW_CTX_TRY_NUMBER='1' AIRFLOW_CTX_DAG_RUN_ID='scheduled__2025-05-27T02:00:00+00:00'
[2025-05-28T09:07:06.374+0000] {animals_api_hook.py:55} INFO - Starting to fetch all animals
[2025-05-28T09:07:06.374+0000] {animals_api_hook.py:33} INFO - Fetching animals page 1
[2025-05-28T09:07:07.403+0000] {animals_api_hook.py:33} INFO - Fetching animals page 1
[2025-05-28T09:07:09.429+0000] {animals_api_hook.py:33} INFO - Fetching animals page 1
[2025-05-28T09:07:09.454+0000] {animals_api_hook.py:77} ERROR - Failed to fetch animals page 1: RetryError[<Future at 0x7f970c1439d0 state=finished raised ExternalAPIException>]
[2025-05-28T09:07:09.466+0000] {taskinstance.py:2731} ERROR - Task failed with exception
Traceback (most recent call last):
  File "/home/airflow/.local/lib/python3.8/site-packages/httpcore/_exceptions.py", line 10, in map_exceptions
    yield
  File "/home/airflow/.local/lib/python3.8/site-packages/httpcore/backends/sync.py", line 94, in connect_tcp
    sock = socket.create_connection(
  File "/usr/local/lib/python3.8/socket.py", line 808, in create_connection
    raise err
  File "/usr/local/lib/python3.8/socket.py", line 796, in create_connection
    sock.connect(sa)
ConnectionRefusedError: [Errno 111] Connection refused

During handling of the above exception, another exception occurred:

Traceback (most recent call last):
  File "/home/airflow/.local/lib/python3.8/site-packages/httpx/_transports/default.py", line 60, in map_httpcore_exceptions
    yield
  File "/home/airflow/.local/lib/python3.8/site-packages/httpx/_transports/default.py", line 218, in handle_request
    resp = self._pool.handle_request(req)
  File "/home/airflow/.local/lib/python3.8/site-packages/httpcore/_sync/connection_pool.py", line 253, in handle_request
    raise exc
  File "/home/airflow/.local/lib/python3.8/site-packages/httpcore/_sync/connection_pool.py", line 237, in handle_request
    response = connection.handle_request(request)
  File "/home/airflow/.local/lib/python3.8/site-packages/httpcore/_sync/connection.py", line 86, in handle_request
    raise exc
  File "/home/airflow/.local/lib/python3.8/site-packages/httpcore/_sync/connection.py", line 63, in handle_request
    stream = self._connect(request)
  File "/home/airflow/.local/lib/python3.8/site-packages/httpcore/_sync/connection.py", line 111, in _connect
    stream = self._network_backend.connect_tcp(**kwargs)
  File "/home/airflow/.local/lib/python3.8/site-packages/httpcore/backends/sync.py", line 94, in connect_tcp
    sock = socket.create_connection(
  File "/usr/local/lib/python3.8/contextlib.py", line 131, in __exit__
    self.gen.throw(type, value, traceback)
  File "/home/airflow/.local/lib/python3.8/site-packages/httpcore/_exceptions.py", line 14, in map_exceptions
    raise to_exc(exc)
httpcore.ConnectError: [Errno 111] Connection refused

The above exception was the direct cause of the following exception:

Traceback (most recent call last):
  File "/opt/airflow/plugins/hooks/animals_api_hook.py", line 37, in get_animals_page
    response = client.get("/animals/v1/animals", params={"page": page})
  File "/home/airflow/.local/lib/python3.8/site-packages/httpx/_client.py", line 1045, in get
    return self.request(
  File "/home/airflow/.local/lib/python3.8/site-packages/httpx/_client.py", line 821, in request
    return self.send(request, auth=auth, follow_redirects=follow_redirects)
  File "/home/airflow/.local/lib/python3.8/site-packages/httpx/_client.py", line 908, in send
    response = self._send_handling_auth(
  File "/home/airflow/.local/lib/python3.8/site-packages/httpx/_client.py", line 936, in _send_handling_auth
    response = self._send_handling_redirects(
  File "/home/airflow/.local/lib/python3.8/site-packages/httpx/_client.py", line 973, in _send_handling_redirects
    response = self._send_single_request(request)
  File "/home/airflow/.local/lib/python3.8/site-packages/httpx/_client.py", line 1009, in _send_single_request
    response = transport.handle_request(request)
  File "/home/airflow/.local/lib/python3.8/site-packages/httpx/_transports/default.py", line 218, in handle_request
    resp = self._pool.handle_request(req)
  File "/usr/local/lib/python3.8/contextlib.py", line 131, in __exit__
    self.gen.throw(type, value, traceback)
  File "/home/airflow/.local/lib/python3.8/site-packages/httpx/_transports/default.py", line 77, in map_httpcore_exceptions
    raise mapped_exc(message) from exc
httpx.ConnectError: [Errno 111] Connection refused

During handling of the above exception, another exception occurred:

Traceback (most recent call last):
  File "/home/airflow/.local/lib/python3.8/site-packages/tenacity/__init__.py", line 382, in __call__
    result = fn(*args, **kwargs)
  File "/opt/airflow/plugins/hooks/animals_api_hook.py", line 51, in get_animals_page
    raise ExternalAPIException(f"Unexpected error: {str(e)}")
utils.exceptions.ExternalAPIException: Unexpected error: [Errno 111] Connection refused

The above exception was the direct cause of the following exception:

Traceback (most recent call last):
  File "/opt/airflow/plugins/hooks/animals_api_hook.py", line 61, in get_all_animals
    paginated_response = self.get_animals_page(page)
  File "/home/airflow/.local/lib/python3.8/site-packages/tenacity/__init__.py", line 289, in wrapped_f
    return self(f, *args, **kw)
  File "/home/airflow/.local/lib/python3.8/site-packages/tenacity/__init__.py", line 379, in __call__
    do = self.iter(retry_state=retry_state)
  File "/home/airflow/.local/lib/python3.8/site-packages/tenacity/__init__.py", line 326, in iter
    raise retry_exc from fut.exception()
tenacity.RetryError: RetryError[<Future at 0x7f970c1439d0 state=finished raised ExternalAPIException>]

During handling of the above exception, another exception occurred:

Traceback (most recent call last):
  File "/home/airflow/.local/lib/python3.8/site-packages/airflow/models/taskinstance.py", line 439, in _execute_task
    result = _execute_callable(context=context, **execute_callable_kwargs)
  File "/home/airflow/.local/lib/python3.8/site-packages/airflow/models/taskinstance.py", line 414, in _execute_callable
    return execute_callable(context=context, **execute_callable_kwargs)
  File "/opt/airflow/plugins/operators/animal_etl_operators.py", line 28, in execute
    animals = hook.get_all_animals()
  File "/opt/airflow/plugins/hooks/animals_api_hook.py", line 78, in get_all_animals
    raise AirflowException(f"Failed to fetch animals: {str(e)}")
airflow.exceptions.AirflowException: Failed to fetch animals: RetryError[<Future at 0x7f970c1439d0 state=finished raised ExternalAPIException>]
[2025-05-28T09:07:09.481+0000] {taskinstance.py:1149} INFO - Marking task as UP_FOR_RETRY. dag_id=animal_etl_pipeline_v1, task_id=extract_animals, execution_date=20250527T020000, start_date=20250528T090706, end_date=20250528T090709
[2025-05-28T09:07:09.495+0000] {standard_task_runner.py:107} ERROR - Failed to execute job 5 for task extract_animals (Failed to fetch animals: RetryError[<Future at 0x7f970c1439d0 state=finished raised ExternalAPIException>]; 66)
[2025-05-28T09:07:09.519+0000] {local_task_job_runner.py:234} INFO - Task exited with return code 1
[2025-05-28T09:07:09.549+0000] {taskinstance.py:3312} INFO - 0 downstream tasks scheduled from follow-on schedule check
