[2025-05-28T09:03:14.465+0000] {taskinstance.py:1979} INFO - Dependencies all met for dep_context=non-requeueable deps ti=<TaskInstance: animal_etl_pipeline.health_check scheduled__2025-05-27T02:00:00+00:00 [queued]>
[2025-05-28T09:03:14.479+0000] {taskinstance.py:1979} INFO - Dependencies all met for dep_context=requeueable deps ti=<TaskInstance: animal_etl_pipeline.health_check scheduled__2025-05-27T02:00:00+00:00 [queued]>
[2025-05-28T09:03:14.479+0000] {taskinstance.py:2193} INFO - Starting attempt 1 of 4
[2025-05-28T09:03:14.499+0000] {taskinstance.py:2217} INFO - Executing <Task(HealthCheckOperator): health_check> on 2025-05-27 02:00:00+00:00
[2025-05-28T09:03:14.505+0000] {standard_task_runner.py:60} INFO - Started process 60 to run task
[2025-05-28T09:03:14.509+0000] {standard_task_runner.py:87} INFO - Running: ['airflow', 'tasks', 'run', 'animal_etl_pipeline', 'health_check', 'scheduled__2025-05-27T02:00:00+00:00', '--job-id', '2', '--raw', '--subdir', 'DAGS_FOLDER/animal_etl_dag.py', '--cfg-path', '/tmp/tmp71h26ifi']
[2025-05-28T09:03:14.511+0000] {standard_task_runner.py:88} INFO - Job 2: Subtask health_check
[2025-05-28T09:03:14.572+0000] {task_command.py:423} INFO - Running <TaskInstance: animal_etl_pipeline.health_check scheduled__2025-05-27T02:00:00+00:00 [running]> on host 432e2a45d2a3
[2025-05-28T09:03:14.668+0000] {taskinstance.py:2513} INFO - Exporting env vars: AIRFLOW_CTX_DAG_EMAIL='admin@company.com' AIRFLOW_CTX_DAG_OWNER='data_team' AIRFLOW_CTX_DAG_ID='animal_etl_pipeline' AIRFLOW_CTX_TASK_ID='health_check' AIRFLOW_CTX_EXECUTION_DATE='2025-05-27T02:00:00+00:00' AIRFLOW_CTX_TRY_NUMBER='1' AIRFLOW_CTX_DAG_RUN_ID='scheduled__2025-05-27T02:00:00+00:00'
[2025-05-28T09:03:14.715+0000] {taskinstance.py:2731} ERROR - Task failed with exception
Traceback (most recent call last):
  File "/home/airflow/.local/lib/python3.8/site-packages/airflow/models/taskinstance.py", line 439, in _execute_task
    result = _execute_callable(context=context, **execute_callable_kwargs)
  File "/home/airflow/.local/lib/python3.8/site-packages/airflow/models/taskinstance.py", line 414, in _execute_callable
    return execute_callable(context=context, **execute_callable_kwargs)
  File "/opt/airflow/plugins/operators/animal_etl_operators.py", line 137, in execute
    raise AirflowException("Animals API health check failed")
airflow.exceptions.AirflowException: Animals API health check failed
[2025-05-28T09:03:14.723+0000] {taskinstance.py:1149} INFO - Marking task as UP_FOR_RETRY. dag_id=animal_etl_pipeline, task_id=health_check, execution_date=20250527T020000, start_date=20250528T090314, end_date=20250528T090314
[2025-05-28T09:03:14.742+0000] {standard_task_runner.py:107} ERROR - Failed to execute job 2 for task health_check (Animals API health check failed; 60)
[2025-05-28T09:03:14.761+0000] {local_task_job_runner.py:234} INFO - Task exited with return code 1
[2025-05-28T09:03:14.793+0000] {taskinstance.py:3312} INFO - 0 downstream tasks scheduled from follow-on schedule check
